<?xml version="1.0"?>
<robot xmlns:xacro="http://www.ros.org/wiki/xacro">
  <!-- Loading some constants -->
  <xacro:include filename="$(find uuv_descriptions)/urdf/common.urdf.xacro"/>
  <!-- Loading file with sensor macros -->
  <xacro:include filename="$(find uuv_sensor_ros_plugins)/urdf/sensor_snippets.xacro"/>
  <!-- Loading the UUV simulator ROS plugin macros -->
  <xacro:include filename="$(find uuv_gazebo_ros_plugins)/urdf/snippets.xacro"/>  
  <!-- Loading vehicle's specific macros 
  <xacro:include filename="$(find uds_description)/urdf/snippets.xacro"/>
  -->
  <!--
    Vehicle's parameters (remember to enter the model parameters below)
  -->

  <xacro:property name="mass" value="26.3"/>
  <!-- Center of gravity -->
  <xacro:property name="cog" value="0 0 -40"/>
  <!-- Fluid density -->
  <xacro:property name="rho" value="1028"/>
  <xacro:property name="namespace" value="uds"/>
  <xacro:property name="camera_link" value="0.008"/>
  <!--
    Visual mesh file for the vehicle, usually in DAE (Collada) format. Be sure to store the
    mesh with the origin of the mesh on the same position of the center of mass, otherwise
    the mesh pose will have to be corrected below in the <visual> block.
    Open the meshes for the RexROV vehicle in Blender to see an example on the mesh placement.
  -->
  <xacro:property name="visual_mesh_file_camera" value="file://$(find uds_description)/meshes/camera_cylinder.dae"/>
  <xacro:property name="visual_mesh_file_body" value="file://$(find uds_description)/meshes/sss_FINAL2_orgin.dae"/>

  <!-- Collision geometry mesh, usually in STL format (it is recommended to keep
  this geometry as simple as possible to improve the performance the physics engine
  regarding the computation of collision forces) -->
 
  
  <!-- Vehicle macro -->
  <xacro:macro name="uds_base" params="namespace *gazebo inertial_reference_frame">  
<!--
      <link name="${inertial_reference_framei}" type="fixed"/>
      <joint name="${inertial_reference_frame}_joint" type="fixed">
        <parent link="${inertial_reference_frame}"/>
        <child link="${namespace}/base_link"/>
        <origin xyz="0 0 0" rpy="0 0 0"/>
      </joint>
  -->
      <!-- Rigid body description of the base link -->
      <link name="${namespace}/base_link">
        <!--
          Be careful to setup the coefficients for the inertial tensor,
          otherwise your model will become unstable on Gazebo
        -->
        <inertial>
          <mass value="${mass}" />
          <origin xyz="${cog}" rpy="0 0 0"/>
          <inertia ixx="525.39" ixy="1.44" ixz="33.41" iyy="794.20" iyz="2.6" izz="691.23"/>

        </inertial>

        <visual>
          <origin xyz="0 0 0" rpy="0 0 0"/>
          <geometry>
            <mesh filename="${visual_mesh_file_body}" scale="1 1 1" />
          </geometry>
        </visual>

        <collision>
          <origin xyz="0 0 0" rpy="0 0 0"/>
          <geometry>
            <mesh filename="${visual_mesh_file_body}" scale="1 1 1" />
          </geometry>
        </collision>
      </link>

      <joint name="${namespace}/left_camera_joint" type="revolute">
        <parent link="${namespace}/base_link"/>
        <child link="${namespace}/left_camera_link"/>
        <origin xyz="-0.35 -0.35 -0" rpy="${pi} 0 0"/>
        <axis xyz="0 1 0"/>
        <limit effort="300" velocity="0.1" lower="${-pi/4}" upper="${pi/4}"/>
      </joint>

      <link name="${namespace}/left_camera_link">
        <inertial>
            <origin xyz="-0.35 -0.35 0" rpy="0 ${pi} 0"/>
            <mass value="0.001"/>
            <inertia ixx="0.01" ixy="0.0" ixz="0.01" iyy="0.0" iyz="0.0" izz="0.01"/>
        </inertial>
        
        <collision>
            <origin xyz="0 0 0" rpy="0 0 0"/>
            <geometry>
                <mesh filename="${visual_mesh_file_camera}" scale="1 1 1"/>
            </geometry>
        </collision>
        <visual>
            <origin xyz="0 0 0" rpy="0 0 0"/>
            <geometry>
                <mesh filename="${visual_mesh_file_camera}" scale="1 1 1" />
            </geometry>
        </visual>
        
      </link>

      <joint name="${namespace}/left_camera_optical_joint" type="fixed">
        <axis xyz="0 0 1"/>
        <origin xyz="0 0 -0.11" rpy="0 0 0"/>
        <parent link="${namespace}/left_camera_link"/>
        <child link="${namespace}/left_camera_optical_link"/>
      </joint>

      <link name="${namespace}/left_camera_optical_link">
      </link>  

      <!-- right camera sensor import -->
      <joint name="${namespace}/right_camera_joint" type="revolute">
        <parent link="${namespace}/base_link"/>
        <child link="${namespace}/right_camera_link"/>
        <origin xyz="0.35 -0.35 -0" rpy="${pi} 0 0"/>
        <axis xyz="0 1 0"/>
        <limit effort="300" velocity="0.1" lower="${-pi/4}" upper="${pi/4}"/>
      </joint>

      <link name="${namespace}/right_camera_link">
      <inertial>
            <origin xyz="-0.35 -0.35 0" rpy="0 ${pi} 0"/>
            <mass value="0.001"/>
            <inertia ixx="0.01" ixy="0.0" ixz="0.01" iyy="0.0" iyz="0.0" izz="0.01"/>
        </inertial>
        
        <collision>
            <origin xyz="0 0 0" rpy="0 0 0"/>
            <geometry>
                <mesh filename="${visual_mesh_file_camera}" scale="1 1 1"/>
            </geometry>
        </collision>
        <visual>
            <origin xyz="0 0 0" rpy="0 0 0"/>
            <geometry>
                <mesh filename="${visual_mesh_file_camera}" scale="1 1 1" />
            </geometry>
        </visual>
        
      </link>

      <joint name="${namespace}/right_camera_optical_joint" type="fixed">
        <axis xyz="0 0 1"/>
        <origin xyz="0 0 -0.11" rpy="0 0 0"/>
        <parent link="${namespace}/right_camera_link"/>
        <child link="${namespace}/right_camera_optical_link"/>
      </joint>

      <link name="${namespace}/right_camera_optical_link">

      </link> 


    <gazebo reference="${namespace}/base_link">
      <selfCollide>false</selfCollide>
    </gazebo>

    <transmission name="tran1">
    <type>transmission_interface/SimpleTransmission</type>
    <joint name="${namespace}/left_camera_joint">
      <hardwareInterface>EffortJointInterface</hardwareInterface>
    </joint>
    <actuator name="motor1">
      <hardwareInterface>EffortJointInterface</hardwareInterface>
      <mechanicalReduction>1</mechanicalReduction>
    </actuator>
  </transmission>
  
    <transmission name="tran2">
      <type>transmission_interface/SimpleTransmission</type>
      <joint name="${namespace}/right_camera_joint">
        <hardwareInterface>EffortJointInterface</hardwareInterface>
      </joint>
      <actuator name="motor2">
        <hardwareInterface>EffortJointInterface</hardwareInterface>
        <mechanicalReduction>1</mechanicalReduction>
      </actuator>
    </transmission>
  
    <gazebo>
      <plugin name="gazebo_ros_control" filename="libgazebo_ros_control.so">
      </plugin>
    </gazebo>
    <!--
    <gazebo reference="${namespace}/base_link">
      <turnGravityOff>true</turnGravityOff>
     </gazebo>
     -->
     <!--
     <gazebo reference="left_camera_link">
      <turnGravityOff>true</turnGravityOff>
     </gazebo>

     <gazebo reference="left_camera_optical_link">
      <turnGravityOff>true</turnGravityOff>
     </gazebo>
     
     <gazebo reference="right_camera_link">
      <turnGravityOff>true</turnGravityOff>
     </gazebo>

     <gazebo reference="right_camera_link_optical">
      <turnGravityOff>true</turnGravityOff>
     </gazebo>
     -->
     
    <!-- Set up hydrodynamic plugin given as input parameter -->
    <xacro:insert_block name="gazebo"/>

    <!-- Include the thruster modules  -->
    <xacro:include filename="$(find uds_description)/urdf/actuators.xacro"/>
   
    <!-- Include the sensor modules 
    <xacro:include filename="$(find uds_description)/urdf/sensors.xacro"/>
    -->
  </xacro:macro>

</robot>
